<?xml version="1.0" ?>
<mujoco model="t2_ollama1_V-A">
  <compiler angle="radian" meshdir="assets" autolimits="true"/>
  <option timestep="0.0005" integrator="implicitfast" cone="elliptic" impratio="10"/>
  <visual>
    <headlight ambient="0.5 0.5 0.5" diffuse="0.6 0.6 0.6" specular="0.2 0.2 0.2"/>
    <global offwidth="1280" offheight="960" azimuth="140" elevation="-20"/>
  </visual>
  <default>
    <geom solref="0.001 1.0" solimp="0.99 0.9999 0.0001" friction="0.3 0.005 0.0001" condim="4" density="0"/>
  </default>
  <asset>
    <material name="base" rgba="0.35 0.65 0.85 1"/>
    <material name="mover" rgba="0.95 0.62 0.25 1"/>
    <material name="hardware" rgba="0.8 0.8 0.85 1"/>
    <material name="other" rgba="0.6 0.75 0.6 1"/>
    <mesh name="P1_vis" file="ollama1_P1_vis.stl"/>
    <mesh name="P2_vis" file="ollama1_P2_vis.stl"/>
    <mesh name="P3_vis" file="ollama1_P3_vis.stl"/>
  </asset>
  <worldbody>
    <light pos="0.15 -0.25 0.4" dir="-0.3 0.5 -1" directional="true" diffuse="0.5 0.5 0.5"/>
    <camera name="iso" pos="0.125 -0.125 0.115" xyaxes="0.707 0.707 0 -0.38 0.38 0.84"/>
    <body name="P1" pos="0 0 0">
      <inertial pos="-0.000130938 -0.000168788 0.014817273" mass="0.038501873" fullinertia="0.000026438116 0.000037494921 0.000050469430 0.000000000851 0.000000079863 0.000000267464"/>
      <geom name="P1_vis" type="mesh" mesh="P1_vis" contype="0" conaffinity="0" group="2" material="base"/>
      <geom name="P1_c0" type="box" pos="0.000000000 0.000000000 0.001000000" size="0.040000000 0.030000000 0.001000000" group="3" material="base" contype="1" conaffinity="1"/>
      <geom name="P1_c1" type="box" pos="0.000000000 -0.029000000 0.020000000" size="0.040000000 0.001000000 0.020000000" group="3" material="base" contype="1" conaffinity="1"/>
      <geom name="P1_c2" type="box" pos="0.000000000 0.029000000 0.020000000" size="0.040000000 0.001000000 0.020000000" group="3" material="base" contype="1" conaffinity="1"/>
      <geom name="P1_c3" type="box" pos="-0.039000000 0.000000000 0.020000000" size="0.001000000 0.028000000 0.020000000" group="3" material="base" contype="1" conaffinity="1"/>
      <geom name="P1_c4" type="box" pos="0.039000000 0.000000000 0.020000000" size="0.001000000 0.028000000 0.020000000" group="3" material="base" contype="1" conaffinity="1"/>
    </body>
    <body name="P2" pos="0 0 0">
      <joint name="hinge" type="hinge" axis="1.000000000 0.000000000 0.000000000" pos="0.000000000 -0.034000000 0.040000000" damping="0.002" range="-0.02 1.92" limited="true"/>
      <inertial pos="0.000466138 -0.002893241 0.040963340" mass="0.020266899" fullinertia="0.000007417262 0.000010324339 0.000017549622 -0.000000027333 0.000000067536 -0.000000272185"/>
      <geom name="P2_vis" type="mesh" mesh="P2_vis" contype="0" conaffinity="0" group="2" material="mover"/>
      <geom name="P2_c0" type="box" pos="0.000000000 0.000000000 0.041500000" size="0.039800000 0.029800000 0.001500000" group="3" material="mover" contype="1" conaffinity="1"/>
      <site name="tip" pos="0.000000000 0.030000000 0.040000000" size="0.002" rgba="1 0.2 0.2 1"/>
    </body>
    <body name="P3" pos="0 0 0">
      <inertial pos="-0.000000000 -0.034000000 0.040000000" mass="0.000487545" fullinertia="0.000000000973 0.000000038530 0.000000038530 0.000000000000 -0.000000000000 -0.000000000000"/>
      <geom name="P3_vis" type="mesh" mesh="P3_vis" contype="0" conaffinity="0" group="2" material="hardware"/>
    </body>
  </worldbody>
</mujoco>
