<?xml version="1.0" ?>
<mujoco model="m0_hinge_box_V-A">
  <compiler angle="radian" meshdir="meshes" autolimits="true"/>
  <option timestep="0.0005" integrator="implicitfast" cone="elliptic" impratio="10"/>
  <visual>
    <headlight ambient="0.5 0.5 0.5" diffuse="0.6 0.6 0.6" specular="0.2 0.2 0.2"/>
    <global offwidth="1280" offheight="960" azimuth="140" elevation="-20"/>
    <rgba haze="0.9 0.93 0.96 1"/>
  </visual>
  <default>
    <geom solref="0.001 1.0" solimp="0.99 0.9999 0.0001" friction="0.3 0.005 0.0001" condim="4" density="0"/>
  </default>
  <asset>
    <texture name="grid" type="2d" builtin="checker" rgb1=".15 .17 .2" rgb2=".22 .24 .28" width="300" height="300"/>
    <material name="grid" texture="grid" texrepeat="6 6" reflectance=".1"/>
    <material name="petg" rgba="0.35 0.65 0.85 1"/>
    <material name="petg_lid" rgba="0.95 0.62 0.25 1"/>
    <material name="steel" rgba="0.8 0.8 0.85 1"/>
    <mesh name="box_shell_vis" file="box_shell_visual.stl"/>
    <mesh name="lid_panel_vis" file="lid_panel_visual.stl"/>
    <mesh name="hinge_pin_vis" file="hinge_pin_visual.stl"/>
  </asset>
  <worldbody>
    <light pos="0.15 -0.25 0.4" dir="-0.3 0.5 -1" directional="true" diffuse="0.5 0.5 0.5"/>
    <light pos="-0.2 0.2 0.3" dir="0.4 -0.4 -1" directional="true" diffuse="0.25 0.25 0.25"/>
    <geom name="floor" type="plane" size="1 1 .05" rgba="0.82 0.85 0.88 1" pos="0 0 0"/>
    <camera name="iso" pos="0.125 -0.125 0.115" xyaxes="0.707 0.707 0 -0.38 0.38 0.84"/>
    <camera name="hinge_closeup" pos="0.065 -0.105 0.085" xyaxes="0.85 0.53 0 -0.32 0.51 0.80"/>
    <body name="box_shell" pos="0 0 0">
      <inertial pos="-0.000000000 -0.000895754 0.015333721" mass="0.039507716" fullinertia="0.000027786203 0.000038421717 0.000051891681 0.000000000000 -0.000000000000 0.000000868629"/>
      <geom name="box_shell_vis" type="mesh" mesh="box_shell_vis" contype="0" conaffinity="0" group="2" material="petg"/>
      <geom name="box_shell_c0" type="box" pos="0.000000000 0.000000000 0.001000000" size="0.040000000 0.030000000 0.001000000" group="3" material="petg"/>
      <geom name="box_shell_c1" type="box" pos="0.000000000 -0.029000000 0.020000000" size="0.040000000 0.001000000 0.020000000" group="3" material="petg"/>
      <geom name="box_shell_c2" type="box" pos="0.000000000 0.029000000 0.020000000" size="0.040000000 0.001000000 0.020000000" group="3" material="petg"/>
      <geom name="box_shell_c3" type="box" pos="-0.039000000 0.000000000 0.020000000" size="0.001000000 0.028000000 0.020000000" group="3" material="petg"/>
      <geom name="box_shell_c4" type="box" pos="0.039000000 0.000000000 0.020000000" size="0.001000000 0.028000000 0.020000000" group="3" material="petg"/>
      <geom name="box_shell_c5" type="cylinder" pos="-0.008300000 -0.034000000 0.041500000" size="0.004000000 0.004000000" group="3" material="petg" euler="0.000000000 1.570796327 0.000000000"/>
      <geom name="box_shell_c6" type="box" pos="-0.008300000 -0.031000000 0.036550000" size="0.004000000 0.003000000 0.002500000" group="3" material="petg"/>
      <geom name="box_shell_c7" type="cylinder" pos="0.008300000 -0.034000000 0.041500000" size="0.004000000 0.004000000" group="3" material="petg" euler="0.000000000 1.570796327 0.000000000"/>
      <geom name="box_shell_c8" type="box" pos="0.008300000 -0.031000000 0.036550000" size="0.004000000 0.003000000 0.002500000" group="3" material="petg"/>
      <site name="box_axis" pos="0.000000000 -0.034000000 0.041500000" size="0.0012" rgba="0.1 0.9 0.2 1"/>
    </body>
    <body name="lid_panel" pos="0 0 0">
      <joint name="hinge" type="hinge" axis="1 0 0" pos="0.000000000 -0.034000000 0.041500000" damping="0.002" range="-0.02 1.745" limited="true"/>
      <inertial pos="0.000000000 -0.000431079 0.041509611" mass="0.018454377" fullinertia="0.000005845828 0.000009579734 0.000015394728 0.000000000000 0.000000000000 0.000000005020"/>
      <geom name="lid_panel_vis" type="mesh" mesh="lid_panel_vis" contype="0" conaffinity="0" group="2" material="petg_lid"/>
      <geom name="lid_panel_c0" type="box" pos="0.000000000 0.000150000 0.041500000" size="0.039800000 0.029650000 0.001500000" group="3" material="petg_lid"/>
      <geom name="lid_panel_c1" type="box" pos="0.000000000 -0.039500000 0.041500000" size="0.003800000 0.002300000 0.001300000" group="3" material="petg_lid"/>
      <geom name="lid_panel_c2" type="cylinder" pos="0.000000000 -0.034000000 0.041500000" size="0.003800000 0.004000000" group="3" material="petg_lid" euler="0.000000000 1.570796327 0.000000000"/>
      <site name="lid_tip" pos="0.000000000 0.030000000 0.041500000" size="0.002" rgba="1 0.2 0.2 1"/>
    </body>
    <body name="hinge_pin" pos="0 0 0">
      <inertial pos="0.000000000 -0.034000000 0.041500000" mass="0.000487545" fullinertia="0.000000000973 0.000000038530 0.000000038530 -0.000000000000 0.000000000000 -0.000000000000"/>
      <geom name="hinge_pin_vis" type="mesh" mesh="hinge_pin_vis" contype="0" conaffinity="0" group="2" material="steel"/>
      <site name="pin_center" pos="0.000000000 -0.034000000 0.041500000" size="0.0012" rgba="0.9 0.1 0.9 1"/>
    </body>
  </worldbody>
</mujoco>
