<?xml version="1.0" ?>
<mujoco model="t2_ld_mesh">
  <compiler angle="radian" autolimits="true" meshdir="/home/ftk3187/github/ASSY/m24_design_closure/out/ld_mesh_assets"/>
  <option timestep="0.0001" integrator="implicitfast" cone="elliptic" impratio="10" gravity="0 0 0"/>
  <visual>
    <headlight ambient="0.5 0.5 0.5" diffuse="0.6 0.6 0.6" specular="0.2 0.2 0.2"/>
    <global offwidth="1280" offheight="960"/>
  </visual>
  <default>
    <geom density="0" contype="0" conaffinity="0" group="2"/>
  </default>
  <asset>
    <material name="cab" rgba="0.60 0.66 0.72 0.30"/>
    <material name="bump" rgba="0.85 0.30 0.30 1"/>
    <material name="drawer" rgba="0.95 0.72 0.35 1"/>
    <material name="clip" rgba="0.20 0.55 0.95 1"/>
    <material name="mk" rgba="0.10 0.85 0.35 1"/>
    <mesh name="m_cabinet_body" file="cabinet_body.stl"/>
    <mesh name="m_bump" file="bump.stl"/>
    <mesh name="m_drawer_body" file="drawer_body.stl"/>
    <mesh name="m_clip" file="clip.stl"/>
  </asset>
  <worldbody>
    <light pos="0.02 -0.2 0.3" dir="-0.05 0.3 -1" directional="true" diffuse="0.5 0.5 0.5"/>
    <camera name="cutaway" pos="0.03 -0.12 0.055" xyaxes="1 0 0 0 0.4 0.92"/>
    <camera name="zoom" pos="0.020 -0.045 0.020" xyaxes="1 0 0 0 0.5 0.87"/>
    <geom name="cab_mesh" type="mesh" mesh="m_cabinet_body" material="cab"/>
    <geom name="bump_mesh" type="mesh" mesh="m_bump" material="bump"/>
    <body name="drawer" pos="0 0 0">
      <inertial mass="0.050000" pos="0.010595 0.000167 0.010339" diaginertia="2.432443e-05 2.036792e-05 4.147441e-05"/>
      <joint name="drawer_slide" type="slide" axis="1 0 0" pos="0 0 0" limited="true" range="0 0.050000" damping="150" solreflimit="0.002 1" solimplimit="0.99 0.9999 1e-5 0.5 2"/>
      <geom name="dr_mesh" type="mesh" mesh="m_drawer_body" material="drawer"/>
      <geom name="clip_mesh" type="mesh" mesh="m_clip" material="clip"/>
      <geom name="mk_drawer" type="box" pos="0.030 -0.030 0.012" size="0.004 0.0015 0.004" material="mk"/>
    </body>
  </worldbody>
  <equality>
    <joint name="latch" joint1="drawer_slide" polycoef="0 0 0 0 0" active="false" solref="-1e8 -1e4" solimp="0.9999 0.99999 1e-6 0.5 2"/>
  </equality>
  <actuator>
    <velocity name="drive" joint="drawer_slide" kv="600"/>
  </actuator>
</mujoco>
