<?xml version="1.0" ?>
<mujoco model="t2_latch">
  <compiler angle="radian" autolimits="true"/>
  <option timestep="0.0001" integrator="implicitfast" cone="elliptic" impratio="10" gravity="0 0 0"/>
  <visual>
    <headlight ambient="0.5 0.5 0.5" diffuse="0.6 0.6 0.6" specular="0.2 0.2 0.2"/>
    <global offwidth="1280" offheight="960"/>
  </visual>
  <default>
    <geom density="0" contype="0" conaffinity="0" group="2"/>
  </default>
  <asset>
    <material name="cab" rgba="0.60 0.66 0.72 1"/>
    <material name="recv" rgba="0.85 0.30 0.30 1"/>
    <material name="drawer" rgba="0.95 0.72 0.35 1"/>
    <material name="hook" rgba="0.20 0.55 0.95 1"/>
    <material name="mk" rgba="0.10 0.85 0.35 1"/>
  </asset>
  <worldbody>
    <light pos="0.02 -0.2 0.3" dir="-0.05 0.3 -1" directional="true" diffuse="0.5 0.5 0.5"/>
    <camera name="cutaway" pos="0.03 -0.11 0.05" xyaxes="1 0 0 0 0.4 0.92"/>
    <camera name="zoom" pos="0.040 -0.040 0.024" xyaxes="1 0 0 0 0.45 0.89"/>
    <geom name="cab_floor" type="box" pos="0.03 0 -0.001" size="0.055999999999999994 0.018 0.0015" material="cab"/>
    <geom name="cab_farwall" type="box" pos="0.03 0.017 0.009" size="0.055999999999999994 0.0015 0.010" material="cab"/>
    <geom name="cab_back" type="box" pos="-0.026 0 0.009" size="0.0015 0.017 0.010" material="cab"/>
    <geom name="receiver" type="box" pos="0.0375 0 0.0170" size="0.0032 0.006 0.0013" material="recv"/>
    <geom name="recv_ramp" type="box" pos="0.0405 0 0.0158" euler="0 35 0" size="0.0016 0.006 0.0010" material="recv"/>
    <body name="drawer" pos="0 0 0">
      <joint name="drawer_slide" type="slide" axis="1 0 0" pos="0 0 0" limited="true" range="0 0.060000" damping="150" solreflimit="0.002 1" solimplimit="0.99 0.9999 1e-5 0.5 2"/>
      <geom name="dr_floor" type="box" pos="0 0 0.003" size="0.020 0.015 0.0015" material="drawer" mass="0.04"/>
      <geom name="dr_back" type="box" pos="-0.019 0 0.008" size="0.0015 0.015 0.005" material="drawer" mass="0.004"/>
      <geom name="dr_farwall" type="box" pos="0 0.014 0.008" size="0.020 0.0012 0.005" material="drawer" mass="0.004"/>
      <geom name="latch_arm" type="box" pos="0.028 0 0.0105" size="0.008 0.0018 0.0011" material="hook" mass="0.002"/>
      <geom name="latch_barb" type="box" pos="0.0355 0 0.0128" size="0.0016 0.0018 0.0026" material="hook" mass="0.001"/>
      <geom name="latch_ramp" type="box" pos="0.0375 0 0.0128" euler="0 35 0" size="0.0016 0.0018 0.0009" material="hook" mass="0.0005"/>
      <geom name="mk_drawer" type="box" pos="0 -0.012 0.006" size="0.004 0.0015 0.004" material="mk"/>
    </body>
  </worldbody>
  <equality>
    <joint name="latch" joint1="drawer_slide" polycoef="0 0 0 0 0" active="false" solref="-1e8 -1e4" solimp="0.9999 0.99999 1e-6 0.5 2"/>
  </equality>
  <actuator>
    <velocity name="drive" joint="drawer_slide" kv="600"/>
  </actuator>
</mujoco>
