<?xml version="1.0" ?>
<mujoco model="t2_ujoint_VA">
  <compiler angle="radian" autolimits="true"/>
  <option timestep="0.0001" integrator="implicitfast" cone="elliptic" impratio="10" gravity="0 0 0"/>
  <visual>
    <headlight ambient="0.5 0.5 0.5" diffuse="0.6 0.6 0.6" specular="0.2 0.2 0.2"/>
    <global offwidth="1280" offheight="960"/>
  </visual>
  <default>
    <geom density="0" contype="0" conaffinity="0" group="2"/>
  </default>
  <asset>
    <material name="base" rgba="0.35 0.65 0.85 1"/>
    <material name="input" rgba="0.95 0.62 0.25 1"/>
    <material name="cross" rgba="0.75 0.75 0.80 1"/>
    <material name="output" rgba="0.55 0.78 0.55 1"/>
    <material name="mk_in" rgba="0.90 0.10 0.10 1"/>
    <material name="mk_cross" rgba="0.10 0.85 0.90 1"/>
    <material name="mk_out" rgba="0.85 0.10 0.80 1"/>
  </asset>
  <worldbody>
    <light pos="0.1 -0.2 0.3" dir="-0.2 0.4 -1" directional="true" diffuse="0.5 0.5 0.5"/>
    <camera name="side" pos="0 -0.16 0.0" xyaxes="1 0 0 0 0 1"/>
    <geom name="base" type="box" pos="0 0 -0.03" size="0.022 0.022 0.002" material="base"/>
    <site name="wtip" pos="0.020000000 0.000000000 0.034641016" size="0.0012"/>
    <body name="input" pos="0 0 0">
      <joint name="jin" type="hinge" axis="0 0 1" pos="0 0 0" damping="1e-05" armature="1e-05"/>
      <geom name="in_shaft" type="cylinder" fromto="0 0 -0.026 0 0 0" size="0.004" material="input" mass="0.01"/>
      <geom name="in_yoke" type="cylinder" fromto="0 0 -0.003 0 0 0.014" size="0.008" material="input" mass="0.006"/>
      <geom name="mk_in" type="box" pos="0.010000000 0.000000000 0.006000000" size="0.003000000 0.001000000 0.004000000" material="mk_in"/>
      <body name="cross" pos="0 0 0">
        <joint name="pin1" type="hinge" axis="1 0 0" pos="0 0 0" damping="1e-05" armature="1e-05"/>
        <geom name="cross_x" type="box" size="0.012 0.002 0.002" material="cross" mass="0.001"/>
        <geom name="cross_y" type="box" size="0.002 0.012 0.002" material="cross" mass="0.001"/>
        <geom name="mk_cross" type="box" pos="0.000000000 0.013000000 0.000000000" size="0.001500000 0.003000000 0.001500000" material="mk_cross"/>
        <body name="output" pos="0 0 0">
          <joint name="pin2" type="hinge" axis="0 1 0" pos="0 0 0" damping="1e-05" armature="1e-05"/>
          <geom name="out_shaft" type="cylinder" fromto="0 0 0 0.019999999999999997 0.0 0.034641016151377546" size="0.004" material="output" mass="0.01"/>
          <site name="otip" pos="0.020000000 0.000000000 0.034641016" size="0.0012"/>
          <site name="omark" pos="0 0.012 0" size="0.0012"/>
          <geom name="mk_out" type="box" pos="0.000000000 0.013000000 0.010000000" size="0.001500000 0.004000000 0.001500000" material="mk_out"/>
        </body>
      </body>
    </body>
  </worldbody>
  <equality>
    <connect body1="output" body2="world" anchor="0.020000000 0.000000000 0.034641016" solref="0.0002 1" solimp="0.99 0.999 1e-4 0.5 2"/>
  </equality>
  <actuator>
    <velocity name="drive" joint="jin" kv="0.5"/>
  </actuator>
</mujoco>
